<?xml version="1.0" encoding="utf-8"?>
<robot
  name="abb_robot">
  <link name="world" />

  <link
    name="base_link">
    <inertial>
      <origin
        xyz="0.00047544 0.11219 -0.023635"
        rpy="0 0 0" />
      <mass
        value="10.645" />
      <inertia
        ixx="0.099513"
        ixy="-0.00016335"
        ixz="0.00055015"
        iyy="0.088938"
        iyz="-0.0006449"
        izz="0.073792" />
    </inertial>
    <visual>
      <origin
        xyz="0 0 0"
        rpy="0 0 0" />
      <geometry>
        <mesh
          filename="file:///home/yahiaraouf/MyStuff/ROS2/ros2_ws/install/abb_robot/share/abb_robot/meshes/base_link.STL" />
      </geometry>
      <material
        name="">
        <color
          rgba="0.78431 0.8 0.78824 1" />
      </material>
    </visual>
    <collision>
      <origin
        xyz="0 0 0"
        rpy="0 0 0" />
      <geometry>
        <mesh
          filename="file:///home/yahiaraouf/MyStuff/ROS2/ros2_ws/install/abb_robot/share/abb_robot/meshes/base_link.STL" />
      </geometry>
    </collision>
  </link>
  <joint name="world_base" type="fixed">
    <parent link="world" />
    <child link="base_link" />
    <origin xyz="0 0 0" rpy="0 0 0" />
  </joint>
  <link
    name="body">
    <inertial>
      <origin
        xyz="-0.0034028 0.00018862 0.10288"
        rpy="0 0 0" />
      <mass
        value="6.0463" />
      <inertia
        ixx="0.075561"
        ixy="4.0309E-05"
        ixz="-0.00050903"
        iyy="0.047881"
        iyz="0.00020826"
        izz="0.055109" />
    </inertial>
    <visual>
      <origin
        xyz="0 0 0"
        rpy="0 0 0" />
      <geometry>
        <mesh
          filename="file:///home/yahiaraouf/MyStuff/ROS2/ros2_ws/install/abb_robot/share/abb_robot/meshes/body.STL" />
      </geometry>
      <material
        name="">
        <color
          rgba="0.79216 0.81961 0.93333 1" />
      </material>
    </visual>
    <collision>
      <origin
        xyz="0 0 0"
        rpy="0 0 0" />
      <geometry>
        <mesh
          filename="file:///home/yahiaraouf/MyStuff/ROS2/ros2_ws/install/abb_robot/share/abb_robot/meshes/body.STL" />
      </geometry>
    </collision>
  </link>
  <joint
    name="joint1_21P0041_21P0240"
    type="revolute">
    <origin
      xyz="0 0 0.21819"
      rpy="0 0 0.36221" />
    <parent
      link="base_link" />
    <child
      link="body" />
    <axis
      xyz="0 0 1" />
    <limit
      lower="-1.57"
      upper="3.14"
      effort="40"
      velocity="3" />
  </joint>
  <link
    name="shoulder">
    <inertial>
      <origin
        xyz="-0.012334 -0.0011597 0.21847"
        rpy="0 0 0" />
      <mass
        value="7.9737" />
      <inertia
        ixx="0.26696"
        ixy="5.9908E-05"
        ixz="-0.0010798"
        iyy="0.24473"
        iyz="0.00034158"
        izz="0.043196" />
    </inertial>
    <visual>
      <origin
        xyz="0 0 0"
        rpy="0 0 0" />
      <geometry>
        <mesh
          filename="file:///home/yahiaraouf/MyStuff/ROS2/ros2_ws/install/abb_robot/share/abb_robot/meshes/shoulder.STL" />
      </geometry>
      <material
        name="">
        <color
          rgba="0.79216 0.81961 0.93333 1" />
      </material>
    </visual>
    <collision>
      <origin
        xyz="0 0 0"
        rpy="0 0 0" />
      <geometry>
        <mesh
          filename="file:///home/yahiaraouf/MyStuff/ROS2/ros2_ws/install/abb_robot/share/abb_robot/meshes/shoulder.STL" />
      </geometry>
    </collision>
  </link>
  <joint
    name="joint2_21P0041_21P0240"
    type="revolute">
    <origin
      xyz="0 0 0.18091"
      rpy="0 -0.51991 0" />
    <parent
      link="body" />
    <child
      link="shoulder" />
    <axis
      xyz="0 1 0" />
    <limit
      lower="-1.57"
      upper="3.14"
      effort="40"
      velocity="3" />
  </joint>
  <link
    name="upper_arm">
    <inertial>
      <origin
        xyz="0.098118 0.00020436 0.035029"
        rpy="0 0 0" />
      <mass
        value="6.4014" />
      <inertia
        ixx="0.020366"
        ixy="0.00012344"
        ixz="-0.0052118"
        iyy="0.078298"
        iyz="4.3686E-05"
        izz="0.072094" />
    </inertial>
    <visual>
      <origin
        xyz="0 0 0"
        rpy="0 0 0" />
      <geometry>
        <mesh
          filename="file:///home/yahiaraouf/MyStuff/ROS2/ros2_ws/install/abb_robot/share/abb_robot/meshes/upper_arm.STL" />
      </geometry>
      <material
        name="">
        <color
          rgba="0.79216 0.81961 0.93333 1" />
      </material>
    </visual>
    <collision>
      <origin
        xyz="0 0 0"
        rpy="0 0 0" />
      <geometry>
        <mesh
          filename="file:///home/yahiaraouf/MyStuff/ROS2/ros2_ws/install/abb_robot/share/abb_robot/meshes/upper_arm.STL" />
      </geometry>
    </collision>
  </link>
  <joint
    name="joint3_21P0041_21P0240"
    type="revolute">
    <origin
      xyz="0 0 0.448"
      rpy="0 -0.96336 0" />
    <parent
      link="shoulder" />
    <child
      link="upper_arm" />
    <axis
      xyz="0 1 0" />
    <limit
      lower="-1.57"
      upper="3.14"
      effort="40"
      velocity="3" />
  </joint>
  <link
    name="forearm">
    <inertial>
      <origin
        xyz="0.1032 0.0016275 0.0010936"
        rpy="0 0 0" />
      <mass
        value="1.7965" />
      <inertia
        ixx="0.0037469"
        ixy="-0.00017516"
        ixz="6.0651E-05"
        iyy="0.0073524"
        iyz="-1.2613E-06"
        izz="0.0078911" />
    </inertial>
    <visual>
      <origin
        xyz="0 0 0"
        rpy="0 0 0" />
      <geometry>
        <mesh
          filename="file:///home/yahiaraouf/MyStuff/ROS2/ros2_ws/install/abb_robot/share/abb_robot/meshes/forearm.STL" />
      </geometry>
      <material
        name="">
        <color
          rgba="0.79216 0.81961 0.93333 1" />
      </material>
    </visual>
    <collision>
      <origin
        xyz="0 0 0"
        rpy="0 0 0" />
      <geometry>
        <mesh
          filename="file:///home/yahiaraouf/MyStuff/ROS2/ros2_ws/install/abb_robot/share/abb_robot/meshes/forearm.STL" />
      </geometry>
    </collision>
  </link>
  <joint
    name="joint4_21P0041_21P0240"
    type="revolute">
    <origin
      xyz="0.25605 0 0.041973"
      rpy="-1.7374 0 1.639E-05" />
    <parent
      link="upper_arm" />
    <child
      link="forearm" />
    <axis
      xyz="1 0 -1.662E-05" />
    <limit
      lower="-1.57"
      upper="3.14"
      effort="40"
      velocity="3" />
  </joint>
  <link
    name="wrist">
    <inertial>
      <origin
        xyz="0.017848 -0.0024424 5.492E-05"
        rpy="0 0 0" />
      <mass
        value="0.57863" />
      <inertia
        ixx="0.00044316"
        ixy="-2.259E-05"
        ixz="1.4432E-06"
        iyy="0.0011373"
        iyz="-5.6348E-07"
        izz="0.00099796" />
    </inertial>
    <visual>
      <origin
        xyz="0 0 0"
        rpy="0 0 0" />
      <geometry>
        <mesh
          filename="file:///home/yahiaraouf/MyStuff/ROS2/ros2_ws/install/abb_robot/share/abb_robot/meshes/wrist.STL" />
      </geometry>
      <material
        name="">
        <color
          rgba="0.78039 0.8 0.78824 1" />
      </material>
    </visual>
    <collision>
      <origin
        xyz="0 0 0"
        rpy="0 0 0" />
      <geometry>
        <mesh
          filename="file:///home/yahiaraouf/MyStuff/ROS2/ros2_ws/install/abb_robot/share/abb_robot/meshes/wrist.STL" />
      </geometry>
    </collision>
  </link>
  <joint
    name="joint5_21P0041_21P0240"
    type="revolute">
    <origin
      xyz="0.19495 0 0"
      rpy="0 -0.032946 0" />
    <parent
      link="forearm" />
    <child
      link="wrist" />
    <axis
      xyz="0 1 0" />
    <limit
      lower="-1.57"
      upper="3.14"
      effort="40"
      velocity="3" />
  </joint>
  <link
    name="hand">
    <inertial>
      <origin
        xyz="0.0099757 0.0011559 0.0020465"
        rpy="0 0 0" />
      <mass
        value="0.033106" />
      <inertia
        ixx="9.0762E-06"
        ixy="2.1259E-13"
        ixz="-1.3087E-10"
        iyy="4.7669E-06"
        iyz="-1.9199E-08"
        izz="4.4168E-06" />
    </inertial>
    <visual>
      <origin
        xyz="0 0 0"
        rpy="0 0 0" />
      <geometry>
        <mesh
          filename="file:///home/yahiaraouf/MyStuff/ROS2/ros2_ws/install/abb_robot/share/abb_robot/meshes/hand.STL" />
      </geometry>
      <material
        name="">
        <color
          rgba="0.78039 0.8 0.78824 1" />
      </material>
    </visual>
    <collision>
      <origin
        xyz="0 0 0"
        rpy="0 0 0" />
      <geometry>
        <mesh
          filename="file:///home/yahiaraouf/MyStuff/ROS2/ros2_ws/install/abb_robot/share/abb_robot/meshes/hand.STL" />
      </geometry>
    </collision>
  </link>
  <joint
    name="joint6_21P0041_21P0240"
    type="revolute">
    <origin
      xyz="0.086445 -1.3927E-05 0"
      rpy="-2.9799 0 0" />
    <parent
      link="wrist" />
    <child
      link="hand" />
    <axis
      xyz="1 0 0" />
    <limit
      lower="-1.57"
      upper="3.14"
      effort="40"
      velocity="3" />
  </joint>
  <link
    name="finger2">
    <inertial>
      <origin
        xyz="0.010808 0.029123 -0.018713"
        rpy="0 0 0" />
      <mass
        value="0.0035587" />
      <inertia
        ixx="2.2382E-07"
        ixy="4.7493E-14"
        ixz="1.7906E-15"
        iyy="1.1432E-07"
        iyz="3.897E-08"
        izz="2.4651E-07" />
    </inertial>
    <visual>
      <origin
        xyz="0 0 0"
        rpy="0 0 0" />
      <geometry>
        <mesh
          filename="file:///home/yahiaraouf/MyStuff/ROS2/ros2_ws/install/abb_robot/share/abb_robot/meshes/finger2.STL" />
      </geometry>
      <material
        name="">
        <color
          rgba="0.79216 0.81961 0.93333 1" />
      </material>
    </visual>
    <collision>
      <origin
        xyz="0 0 0"
        rpy="0 0 0" />
      <geometry>
        <mesh
          filename="file:///home/yahiaraouf/MyStuff/ROS2/ros2_ws/install/abb_robot/share/abb_robot/meshes/finger2.STL" />
      </geometry>
    </collision>
  </link>
  <joint
    name="joint7_21P0041_21P0240"
    type="prismatic">
    <origin
      xyz="0.011988 0.026847 0.026335"
      rpy="0 -0.50354 -1.5708" />
    <parent
      link="hand" />
    <child
      link="finger2" />
    <axis
      xyz="0 1 0" />
    <limit
      lower="-1.57"
      upper="3.14"
      effort="0"
      velocity="0" />
  </joint>
  <link
    name="finger1">
    <inertial>
      <origin
        xyz="0.010683 0.019123 -0.051029"
        rpy="0 0 0" />
      <mass
        value="0.0035587" />
      <inertia
        ixx="2.2382E-07"
        ixy="-1.8553E-13"
        ixz="-3.7404E-14"
        iyy="1.1432E-07"
        iyz="-3.897E-08"
        izz="2.4651E-07" />
    </inertial>
    <visual>
      <origin
        xyz="0 0 0"
        rpy="0 0 0" />
      <geometry>
        <mesh
          filename="file:///home/yahiaraouf/MyStuff/ROS2/ros2_ws/install/abb_robot/share/abb_robot/meshes/finger1.STL" />
      </geometry>
      <material
        name="">
        <color
          rgba="0.79216 0.81961 0.93333 1" />
      </material>
    </visual>
    <collision>
      <origin
        xyz="0 0 0"
        rpy="0 0 0" />
      <geometry>
        <mesh
          filename="file:///home/yahiaraouf/MyStuff/ROS2/ros2_ws/install/abb_robot/share/abb_robot/meshes/finger1.STL" />
      </geometry>
    </collision>
  </link>
  <joint
    name="joint8_21P0041_21P0240"
    type="prismatic">
    <origin
      xyz="0.021988 0.026847 0.026335"
      rpy="0 -0.50354 -1.5708" />
    <parent
      link="hand" />
    <child
      link="finger1" />
    <axis
      xyz="0 1 0" />
    <limit
      lower="0"
      upper="3.14"
      effort="0"
      velocity="0" />
  </joint>

  <ros2_control name="RobotSystem" type="system">
    <hardware>
      <plugin>gz_ros2_control/GazeboSimSystem</plugin>
    </hardware>
    <joint name="joint1_21P0041_21P0240">
      <command_interface name="position" />
      <state_interface name="position">
        <param name="initial_value">0.0</param>
      </state_interface>
      <state_interface name="velocity">
        <param name="initial_value">0.0</param>
      </state_interface>
    </joint>

    <joint name="joint2_21P0041_21P0240">
      <command_interface name="position" />
      <state_interface name="position">
        <param name="initial_value">0.0</param>
      </state_interface>
      <state_interface name="velocity">
        <param name="initial_value">0.0</param>
      </state_interface>
    </joint>

    <joint name="joint3_21P0041_21P0240">
      <command_interface name="position" />
      <state_interface name="position">
        <param name="initial_value">0.0</param>
      </state_interface>
      <state_interface name="velocity">
        <param name="initial_value">0.0</param>
      </state_interface>
    </joint>

    <joint name="joint4_21P0041_21P0240">
      <command_interface name="position" />
      <state_interface name="position">
        <param name="initial_value">0.0</param>
      </state_interface>
      <state_interface name="velocity">
        <param name="initial_value">0.0</param>
      </state_interface>
    </joint>

    <joint name="joint5_21P0041_21P0240">
      <command_interface name="position" />
      <state_interface name="position">
        <param name="initial_value">0.0</param>
      </state_interface>
      <state_interface name="velocity">
        <param name="initial_value">0.0</param>
      </state_interface>
    </joint>

    <joint name="joint6_21P0041_21P0240">
      <command_interface name="position" />
      <state_interface name="position">
        <param name="initial_value">0.0</param>
      </state_interface>
      <state_interface name="velocity">
        <param name="initial_value">0.0</param>
      </state_interface>
    </joint>

    <joint name="joint7_21P0041_21P0240">
      <command_interface name="position" />
      <state_interface name="position">
        <param name="initial_value">0.0</param>
      </state_interface>
      <state_interface name="velocity">
        <param name="initial_value">0.0</param>
      </state_interface>
    </joint>

    <joint name="joint8_21P0041_21P0240">
      <command_interface name="position" />
      <state_interface name="position">
        <param name="initial_value">0.0</param>
      </state_interface>
      <state_interface name="velocity">
        <param name="initial_value">0.0</param>
      </state_interface>
    </joint>

  </ros2_control>

  <gazebo>
    <plugin filename="gz_ros2_control-system"
      name="gz_ros2_control::GazeboSimROS2ControlPlugin">
      <parameters>
        /home/yahiaraouf/MyStuff/ROS2/ros2_ws/install/abb_robot/share/abb_robot/config/joint_controller.yaml </parameters>
    </plugin>
  </gazebo>

</robot>